<?xml version='1.0'?>

<robot name="mark1" xmlns:xacro="http://www.ros.org/wiki/xacro">


  <xacro:include filename="$(find mark1)/src/mark1_description/urdf/mark1.gazebo" />
  <xacro:include filename="$(find mark1)/src/mark1_description/urdf/materials.xacro" />
  <xacro:include filename="$(find mark1)/src/mark1_description/urdf/macros.xacro" />


  <link name="base_link">
    <inertial>
      <origin
        xyz="0.00096237 -0.01836 0.0013951"
        rpy="0 0 0" />
      <mass
        value="10.207" />
      <inertia
         ixx="0.5" ixy="0" ixz="0"
          iyy="1.0" iyz="0"
          izz="0.1" />
    </inertial>
    <visual>
      <origin
        xyz="0 0 0"
        rpy="0 0 0" />
      <geometry>
        <mesh
          filename="package://mark1/src/mark1_description/meshes/base_link.STL" />
      </geometry>
      <material
        name="">
        <color
          rgba="1 1 1 1" />
      </material>
    </visual>
    <collision>
      <origin
        xyz="0 0 0"
        rpy="0 0 0" />
      <geometry>
        <mesh
          filename="package://mark1/src/mark1_description/meshes/base_link.STL" />
      </geometry>
    </collision>
  </link>
  <link    name="Left_Motor_Link">
    <inertial>
      <origin
        xyz="-6.9389E-18 -0.029509 1.3878E-17"
        rpy="0 0 0" />
      <mass
        value="1.483" />
      <inertia
        ixx="0.0078938" ixy="1.3747E-18" ixz="-2.0644E-19"
        iyy="0.014347" iyz="-3.4936E-18"
        izz="0.0078938" />
    </inertial>
    <visual>
      <origin
        xyz="0 0 0"
        rpy="0 0 0" />
      <geometry>
        <mesh
          filename="package://mark1/src/mark1_description/meshes/Left_Motor_Link.STL" />
      </geometry>
      <material
        name="">
        <color
          rgba="0.29804 0.29804 0.29804 1" />
      </material>
    </visual>
    <collision>
      <origin
        xyz="0 0 0"
        rpy="0 0 0" />
      <geometry>
        <mesh
          filename="package://mark1/src/mark1_description/meshes/Left_Motor_Link.STL" />
      </geometry>
    </collision>
  </link>
  <joint name="Left_Motor_Joint" type="continuous">
    <origin
      xyz="-0.31944 0.20433 -0.05511"
      rpy="-3.1415 3.1415 3.141" />
    <parent
      link="base_link" />
    <child
      link="Left_Motor_Link" />
    <axis
      xyz="0 1 0" />
  </joint>
  <link name="Right_Motor_Link">
    <inertial>
      <origin
        xyz="0 -0.02951 7.5894E-18"
        rpy="0 0 0" />
      <mass
        value="1.483" />
      <inertia
        ixx="0.0078938"
        ixy="4.2444E-18"
        ixz="-7.123E-20"
        iyy="0.014347"
        iyz="-7.9282E-19"
        izz="0.0078938" />
    </inertial>
    <visual>
      <origin
        xyz="0 0 0"
        rpy="0 0 0" />
      <geometry>
        <mesh
          filename="package://mark1/src/mark1_description/meshes/Right_Motor_Link.STL" />
      </geometry>
      <material
        name="">
        <color
          rgba="0.29804 0.29804 0.29804 1" />
      </material>
    </visual>
    <collision>
      <origin
        xyz="0 0 0"
        rpy="0 0 0" />
      <geometry>
        <mesh
          filename="package://mark1/src/mark1_description/meshes/Right_Motor_Link.STL" />
      </geometry>
    </collision>
  </link>
  <joint  name="Right_Motor_Joint" type="continuous">
    <origin
      xyz="-0.3197 -0.23965 -0.05511"
      rpy="-3.14 3.1415 3.1395" />
    <parent
      link="base_link" />
    <child
      link="Right_Motor_Link" />
    <axis
      xyz="0 1 0" />
  </joint>
 
  <!-- Hokuyo Laser -->
  <link name="hokuyo">
    <collision>
      <origin xyz="0 0 0" rpy="0 0 0"/>
      <geometry>
    <box size="0.1 0.1 0.1"/>
      </geometry>
    </collision>

    <visual>
      <origin xyz="0 0 0" rpy="0 0 0"/>
      <geometry>
        <mesh filename="package://mark1/src/mark1_description/meshes/hokuyo.dae"/>
      </geometry>
    </visual>

    <inertial>
      <mass value="1e-5" />
      <origin xyz="0 0 0" rpy="0 0 0"/>
      <inertia ixx="1e-6" ixy="0" ixz="0" iyy="1e-6" iyz="0" izz="1e-6" />
    </inertial>
  </link>
<joint name="hokuyo_joint" type="fixed">
    <axis xyz="0 1 0" />
    <origin xyz="-0.1 0 0.19" rpy="0 0 0"/>
    <parent link="base_link"/>
    <child link="hokuyo"/>
  </joint>

  <!-- Camera -->
  <link name="camera_link">
  
    <collision>
      <origin xyz="0 0 0" rpy="0 0 0"/>
      <geometry>
    <box size="0 0 0"/>
      </geometry>
    </collision>

    <visual>
      <origin xyz="0 0 0" rpy="0 0 0"/>
      <geometry>
    <box size="0.05 0.05  0.05"/>
      </geometry>
      <material name="red"/>
    </visual>

    <inertial>
      <mass value="1e-5" />
      <origin xyz="0 0 0" rpy="0 0 0"/>
      <inertia ixx="1e-6" ixy="0" ixz="0" iyy="1e-6" iyz="0" izz="1e-6" />
    </inertial>
  </link>
<joint name="camera_joint" type="fixed">
    <axis xyz="0 1 0" />
    <origin xyz="0.27 0 0.05" rpy="0 0  0"/>
    <parent link="base_link"/>
    <child link="camera_link"/>
  </joint>
  
  	  <!-- Depth Camera -->
<link name="depth_camera_link">
  
    <collision>
      <origin xyz="0 0 0" rpy="0 0 0"/>
      <geometry>
    <box size="0.05 0.05 0.05"/>
      </geometry>
    </collision>

    <visual>
      <origin xyz="0 0 0" rpy="0 0 0"/>
      <geometry>
    <box size="0.05 0.05  0.05"/>
      </geometry>
      <material name="blue"/>
    </visual>

    <inertial>
      <mass value="0.210" />
      <origin xyz="0 0 0" rpy="0 0 0"/>
      <inertia ixx="1e-6" ixy="0" ixz="0" iyy="1e-6" iyz="0" izz="1e-6" />
    </inertial>
  </link>
<joint name="depth_camera_joint" type="fixed">

    <axis xyz="0 1 0" />
    <origin xyz="-0.1 0 0.4" rpy="0 0  0"/>
    <parent link="base_link"/>
    <child link="depth_camera_link"/>
  </joint>
 <link name="depth_camera_optical">
  </link>
 <joint name="depth_camera_optical_joint" type="fixed">
    <axis xyz="0 1 0" />
    <origin xyz="0 0 0" rpy="-1.57 0 -1.57"/>
    <parent link="depth_camera_link"/>
    <child link="depth_camera_optical"/>
  </joint>
</robot>


